Workbook

Sheet Setup
B6: {=INDEX(C9:C27,B7)} -> All
B7: 1
C8: Levels | E8: =COUNT(F:F) -> 104 | F8: Full Dates | H8: Timeframes | I8: Start | J8: End
C9: All | E9: Q1 2019 | F9: 43472 | H9: =OFFSET($H$15,K9-1,0) -> 2020 | I9: =OFFSET($I$15,K9-1,0) -> 43836 | J9: =OFFSET($J$15,K9-1,0) -> 44193 | K9: 3
E10: Q1 2019 | F10: 43479 | H10: =OFFSET($H$15,K10-1,0) -> Post-Covid | I10: =OFFSET($I$15,K10-1,0) -> 44046 | J10: =OFFSET($J$15,K10-1,0) -> 44193 | K10: 6
E11: Q1 2019 | F11: 43486 | H11: =OFFSET($H$15,K11-1,0) -> OFF | I11: =OFFSET($I$15,K11-1,0) -> 0 | J11: =OFFSET($J$15,K11-1,0) -> 0 | K11: 1
E12: Q1 2019 | F12: 43493 | H12: =OFFSET($H$15,K12-1,0) -> 0 | I12: =OFFSET($I$15,K12-1,0) -> 0 | J12: =OFFSET($J$15,K12-1,0) -> 0
E13: Q1 2019 | F13: 43500
E14: Q1 2019 | F14: 43507
E15: Q1 2019 | F15: 43514 | H15: OFF
E16: Q1 2019 | F16: 43521 | H16: 2019 | I16: 43472 | J16: 43829
E17: Q1 2019 | F17: 43528 | H17: 2020 | I17: 43836 | J17: 44193
E18: Q1 2019 | F18: 43535 | H18: Covid | I18: 43906 | J18: 44039
E19: Q1 2019 | F19: 43542 | H19: Pre-Covid | I19: 43472 | J19: 43899
E20: Q1 2019 | F20: 43549 | H20: Post-Covid | I20: 44046 | J20: 44193
E21: Q1 2019 | F21: 43556
E22: Q2 2019 | F22: 43563
E23: Q2 2019 | F23: 43570
E24: Q2 2019 | F24: 43577
E25: Q2 2019 | F25: 43584
E26: Q2 2019 | F26: 43591
E27: Q2 2019 | F27: 43598
E28: Q2 2019 | F28: 43605
E29: Q2 2019 | F29: 43612 | I29: Insert cells above to extend
E30: Q2 2019 | F30: 43619
E31: Q2 2019 | F31: 43626
E32: Q2 2019 | F32: 43633
E33: Q2 2019 | F33: 43640
E34: Q2 2019 | F34: 43647
E35: Q3 2019 | F35: 43654
E36: Q3 2019 | F36: 43661
E37: Q3 2019 | F37: 43668
E38: Q3 2019 | F38: 43675
E39: Q3 2019 | F39: 43682
E40: Q3 2019 | F40: 43689
E41: Q3 2019 | F41: 43696
... E112: Q4 2020 | F112: 44193

Sheet Spend Data
G2: 124626
B3: ='Summary Data'!L3 -> 3 | C3: =COUNTA(12:12) -> 25 | D3: =COUNTA(H:H) -> 112 | E3: =Setup!B6 -> All | I3: =COLUMN()-COLUMN(A12) -> 8
H4: col | I4: {=_xlfn.SEQUENCE(1,C3,I3)} -> 8 | J4: 9 | K4: 10 | L4: 11 | M4: 12 | N4: 13 | O4: 14 | P4: 15 | Q4: 16 | R4: 17 | S4: 18 | T4: 19 | U4: 20 | V4: 21 | W4: 22 | X4: 23 | Y4: 24 | Z4: 25 | AA4: 26 | AB4: 27 | AC4: 28 | AD4: 29 | AE4: 30 | AF4: 31 | AG4: 32
B5: =Setup!I9 -> 43836 | C5: =Setup!I10 -> 44046 | D5: =Setup!I11 -> 0 | E5: =Setup!I12 -> 0 | G5: =SUM(_xlfn.ANCHORARRAY(I5)) -> 14744559 | H5: Period 1 | I5: {=SUMIFS(OFFSET(_xlfn.ANCHORARRAY($A$13),0,_xlfn.ANCHORARRAY(I4)),_xlfn.ANCHORARRAY($B$13),">0")} -> 832900.22 | J5: 582657.86 | K5: 1254086.9 | L5: 529716.02 | M5: 168535.15 | N5: 10593.53 | O5: 837914.65 | P5: 0 | Q5: 47981.862 | R5: 169611.57 | S5: 1901742.9 | T5: 107343.93 | U5: 97146.594 | V5: 124626 | W5: 1957070.2 | X5: 1360397.9 | Y5: 2883964.3 | Z5: 1773269.3 | AA5: 105000 | AB5: 0 | AC5: 0 | AD5: 0 | AE5: 0 | AF5: 0 | AG5: 0
B6: =Setup!J9 -> 44193 | C6: =Setup!J10 -> 44193 | D6: =Setup!J11 -> 0 | E6: =Setup!J12 -> 0 | G6: =SUM(_xlfn.ANCHORARRAY(I6)) -> 10036054 | H6: Period 2 | I6: {=SUMIFS(OFFSET(_xlfn.ANCHORARRAY(A13),0,_xlfn.ANCHORARRAY(I4)),_xlfn.ANCHORARRAY(C13),">0")} -> 663704.46 | J6: 464296.45 | K6: 1043922.8 | L6: 305692.7 | M6: 103567.84 | N6: 0 | O6: 790389.56 | P6: 0 | Q6: 29478.214 | R6: 39247.045 | S6: 550304.35 | T6: 107343.93 | U6: 91189.771 | V6: 124626 | W6: 1168467.3 | X6: 1360397.9 | Y6: 2036954.2 | Z6: 1051471 | AA6: 105000 | AB6: 0 | AC6: 0 | AD6: 0 | AE6: 0 | AF6: 0 | AG6: 0
B7: =SMALL(OFFSET($B$12,1,0,$D$3,1),1) -> 53 | C7: =SMALL(OFFSET($C$12,1,0,$D$3,1),1) -> 83 | D7: =SMALL(OFFSET($D$12,1,0,$D$3,1),1) -> #NUM! | E7: =SMALL(OFFSET($E$12,1,0,$D$3,1),1) -> #NUM! | G7: =SUM(_xlfn.ANCHORARRAY(I7)) -> 0 | H7: Period 3 | I7: {=SUMIFS(OFFSET(_xlfn.ANCHORARRAY(A13),0,_xlfn.ANCHORARRAY(I4)),_xlfn.ANCHORARRAY(D13),">0")} -> 0 | J7: 0 | K7: 0 | L7: 0 | M7: 0 | N7: 0 | O7: 0 | P7: 0 | Q7: 0 | R7: 0 | S7: 0 | T7: 0 | U7: 0 | V7: 0 | W7: 0 | X7: 0 | Y7: 0 | Z7: 0 | AA7: 0 | AB7: 0 | AC7: 0 | AD7: 0 | AE7: 0 | AF7: 0 | AG7: 0
B8: =LARGE(OFFSET($B$12,1,0,$D$3,1),1)-B7+1 -> 52 | C8: =LARGE(OFFSET($C$12,1,0,$D$3,1),1)-C7+1 -> 22 | D8: =LARGE(OFFSET($D$12,1,0,$D$3,1),1)-D7+1 -> #NUM! | E8: =LARGE(OFFSET($E$12,1,0,$D$3,1),1)-E7+1 -> #NUM! | G8: =SUM(_xlfn.ANCHORARRAY(I8)) -> 0 | H8: Period 4 | I8: {=SUMIFS(OFFSET(_xlfn.ANCHORARRAY(A13),0,_xlfn.ANCHORARRAY(I4)),_xlfn.ANCHORARRAY(E13),">0")} -> 0 | J8: 0 | K8: 0 | L8: 0 | M8: 0 | N8: 0 | O8: 0 | P8: 0 | Q8: 0 | R8: 0 | S8: 0 | T8: 0 | U8: 0 | V8: 0 | W8: 0 | X8: 0 | Y8: 0 | Z8: 0 | AA8: 0 | AB8: 0 | AC8: 0 | AD8: 0 | AE8: 0 | AF8: 0 | AG8: 0
H9: ="dict["&H10&"]" -> dict[Group 3] | I9: bing_brand_search_spend | J9: google_brand_search_spend | K9: google_display_spend | L9: google_nonbrand_search_spend | M9: google_video_spend | N9: nongoogle_display_spend | O9: nongoogle_video_spend | P9: pinterest_awareness_spend | Q9: pinterest_conversion_spend | R9: print_coop_spend | S9: print_pure_spend | T9: snap_awareness_spend | U9: snap_conversion_spend | V9: tiktok_awareness_spend | W9: tv_coop_spend | X9: tv_pure_spend | Y9: youtube_video_spend | Z9: fbig_spend | AA9: outdoor_spend
G10: from Summary Data | H10: ='Summary Data'!B7 -> Group 3 | I10: {=INDEX(INDIRECT($H$9),MATCH(OFFSET($I$12,0,0,1,$C$3),dict[Group 1],0))} -> Digital Media | J10: Digital Media | K10: Digital Media | L10: Digital Media | M10: Digital Media | N10: Digital Media | O10: Digital Media | P10: Digital Media | Q10: Digital Media | R10: Traditional Media | S10: Traditional Media | T10: Digital Media | U10: Digital Media | V10: Digital Media | W10: Traditional Media | X10: Traditional Media | Y10: Digital Media | Z10: Digital Media | AA10: Traditional Media | AB10: #N/A | AC10: #N/A | AD10: #N/A | AE10: #N/A | AF10: #N/A | AG10: #N/A
I11: Group 1
B12: Period 1 | C12: Period 2 | D12: Period 3 | E12: Period 4 | G12: Level | H12: Date | I12: Search - Brand | J12: Search - Brand | K12: Display | L12: Search - Non-Brand | M12: Online Video | N12: Display | O12: Online Video | P12: Pinterest | Q12: Pinterest | R12: Print - Coop | S12: Print - Pure | T12: Snapchat | U12: Snapchat | V12: TikTok | W12: TV - Coop | X12: TV - Pure | Y12: Online Video | Z12: Facebook Instagram | AA12: Outdoor
A13: {=_xlfn.SEQUENCE(D3)} -> 1 | B13: {=IF((1-ISERROR(SEARCH($E$3,OFFSET($G$12,1,0,$D$3,1))))*(OFFSET($H$12,1,0,$D$3,1)>=B5)*(OFFSET($H$12,1,0,$D$3)<=B6),_xlfn.ANCHORARRAY($A$13),"")} | C13: {=IF((1-ISERROR(SEARCH($E$3,OFFSET($G$12,1,0,$D$3,1))))*(OFFSET($H$12,1,0,$D$3,1)>=C5)*(OFFSET($H$12,1,0,$D$3)<=C6),_xlfn.ANCHORARRAY($A$13),"")} | D13: {=IF((1-ISERROR(SEARCH($E$3,OFFSET($G$12,1,0,$D$3,1))))*(OFFSET($H$12,1,0,$D$3,1)>=D5)*(OFFSET($H$12,1,0,$D$3)<=D6),_xlfn.ANCHORARRAY($A$13),"")} | E13: {=IF((1-ISERROR(SEARCH($E$3,OFFSET($G$12,1,0,$D$3,1))))*(OFFSET($H$12,1,0,$D$3,1)>=E5)*(OFFSET($H$12,1,0,$D$3)<=E6),_xlfn.ANCHORARRAY($A$13),"")} | G13: All | H13: =Setup!F9 -> 43472 | I13: 8535.213 | J13: 5970.834 | K13: 385.81377 | L13: 19863.905 | M13: 1587.0688 | N13: 0 | O13: 0 | P13: 0 | Q13: 0 | R13: 291.8426 | S13: 68696.88 | T13: 0 | U13: 0 | V13: 0 | W13: 0 | X13: 0 | Y13: 6008.7616 | Z13: 0 | AA13: 0
A14: 2 | G14: All | H14: =Setup!F10 -> 43479 | I14: 7213.1737 | J14: 5045.9974 | K14: 193.1763 | L14: 17575.176 | M14: 1892.74 | N14: 0 | O14: 0 | P14: 0 | Q14: 0 | R14: 291.84229 | S14: 128080.38 | T14: 0 | U14: 0 | V14: 0 | W14: 0 | X14: 0 | Y14: 4042.4816 | Z14: 0 | AA14: 0
A15: 3 | G15: All | H15: =Setup!F11 -> 43486 | I15: 7174.7345 | J15: 5019.1072 | K15: 459.46324 | L15: 12181.654 | M15: 1711.4357 | N15: 0 | O15: 0 | P15: 0 | Q15: 0 | R15: 291.84168 | S15: 138871.58 | T15: 0 | U15: 0 | V15: 0 | W15: 0 | X15: 0 | Y15: 3810.1154 | Z15: 0 | AA15: 0
A16: 4 | G16: All | H16: =Setup!F12 -> 43493 | I16: 7815.4707 | J16: 5467.3361 | K16: 552.38057 | L16: 12393.209 | M16: 3413.5203 | N16: 0 | O16: 0 | P16: 0 | Q16: 0 | R16: 13837.331 | S16: 0 | T16: 0 | U16: 0 | V16: 0 | W16: 0 | X16: 0 | Y16: 7283.5619 | Z16: 0 | AA16: 0
A17: 5 | G17: All | H17: =Setup!F13 -> 43500 | I17: 9028.5069 | J17: 6315.9192 | K17: 6625.4674 | L17: 15256.219 | M17: 10973.407 | N17: 0 | O17: 0 | P17: 0 | Q17: 0 | R17: 31897.984 | S17: 102556.37 | T17: 0 | U17: 0 | V17: 0 | W17: 191864.99 | X17: 0 | Y17: 25594.411 | Z17: 0 | AA17: 0
A18: 6 | G18: All | H18: =Setup!F14 -> 43507 | I18: 9331.1159 | J18: 6527.6103 | K18: 17620.744 | L18: 15424.668 | M18: 17235.529 | N18: 0 | O18: 0 | P18: 0 | Q18: 0 | R18: 30455.078 | S18: 0 | T18: 0 | U18: 0 | V18: 0 | W18: 191864.99 | X18: 0 | Y18: 28391.391 | Z18: 0 | AA18: 0
A19: 7 | G19: All | H19: =Setup!F15 -> 43514 | I19: 7430.1603 | J19: 5197.791 | K19: 7583.5941 | L19: 15136.64 | M19: 10726.01 | N19: 0 | O19: 0 | P19: 0 | Q19: 0 | R19: 12580.871 | S19: 172271.21 | T19: 0 | U19: 0 | V19: 0 | W19: 191864.99 | X19: 0 | Y19: 12064.529 | Z19: 0 | AA19: 0
A20: 8 | G20: All | H20: =Setup!F16 -> 43521 | I20: 6198.8048 | J20: 4336.3926 | K20: 8957.4623 | L20: 13790.822 | M20: 6222.9989 | N20: 0 | O20: 0 | P20: 0 | Q20: 0 | R20: 13242.876 | S20: 0 | T20: 0 | U20: 0 | V20: 0 | W20: 0 | X20: 0 | Y20: 9795.5138 | Z20: 0 | AA20: 0
A21: 9 | G21: All | H21: =Setup!F17 -> 43528 | I21: 7126.8902 | J21: 4985.6375 | K21: 8559.8125 | L21: 13539.399 | M21: 9866.5972 | N21: 0 | O21: 0 | P21: 0 | Q21: 0 | R21: 31621.187 | S21: 0 | T21: 0 | U21: 0 | V21: 0 | W21: 28401.068 | X21: 0 | Y21: 9919.1396 | Z21: 0 | AA21: 0
A22: 10 | G22: All | H22: =Setup!F18 -> 43535 | I22: 9041.1667 | J22: 6324.7754 | K22: 11191.914 | L22: 12826.262 | M22: 12756.787 | N22: 0 | O22: 0 | P22: 0 | Q22: 0 | R22: 31806.192 | S22: 124936.11 | T22: 0 | U22: 0 | V22: 0 | W22: 28401.068 | X22: 0 | Y22: 13554.999 | Z22: 0 | AA22: 0
A23: 11 | G23: All | H23: =Setup!F19 -> 43542 | I23: 9687.5569 | J23: 6776.9596 | K23: 14381.077 | L23: 11685.269 | M23: 9198.0748 | N23: 0 | O23: 0 | P23: 0 | Q23: 1466.832 | R23: 1587.1126 | S23: 0 | T23: 0 | U23: 0 | V23: 0 | W23: 28401.068 | X23: 0 | Y23: 19186.103 | Z23: 0 | AA23: 0
A24: 12 | G24: All | H24: =Setup!F20 -> 43549 | I24: 6094.4152 | J24: 4263.3665 | K24: 13680.062 | L24: 13208.833 | M24: 6776.7154 | N24: 0 | O24: 0 | P24: 0 | Q24: 5663.8375 | R24: 476.88065 | S24: 346712.64 | T24: 0 | U24: 0 | V24: 0 | W24: 0 | X24: 0 | Y24: 17619.136 | Z24: 0 | AA24: 0
A25: 13 | G25: All | H25: =Setup!F21 -> 43556 | I25: 5280.9621 | J25: 3694.313 | K25: 4133.3607 | L25: 12834.149 | M25: 5269.9098 | N25: 0 | O25: 0 | P25: 0 | Q25: 1968.2189 | R25: 12306.024 | S25: 0 | T25: 0 | U25: 0 | V25: 0 | W25: 59168.891 | X25: 0 | Y25: 9911.1563 | Z25: 0 | AA25: 0
... A64: 52 | G64: All | H64: =Setup!F60 -> 43829 | I64: 4247.1279 | J64: 2971.0911 | K64: 10290.299 | L64: 14724.083 | M64: 5676.9288 | N64: 0 | O64: 0 | P64: 0 | Q64: 0 | R64: 6939.0537 | S64: 0 | T64: 0 | U64: 0 | V64: 0 | W64: 0 | X64: 0 | Y64: 0 | Z64: 47057.868 | AA64: 0
A65: 53 | B65: 53 | G65: All | H65: =Setup!F61 -> 43836 | I65: 3360.2201 | J65: 2350.6521 | K65: 0 | L65: 12795.007 | M65: 0 | N65: 0 | O65: 0 | P65: 0 | Q65: 0 | R65: 1033.9513 | S65: 0 | T65: 0 | U65: 0 | V65: 0 | W65: 0 | X65: 0 | Y65: 0 | Z65: 37469.96 | AA65: 0
A66: 54 | B66: 54 | G66: All | H66: =Setup!F62 -> 43843 | I66: 3982.1144 | J66: 2785.7001 | K66: 0 | L66: 16597.119 | M66: 0 | N66: 0 | O66: 0 | P66: 0 | Q66: 0 | R66: 1033.9507 | S66: 114707.67 | T66: 0 | U66: 0 | V66: 0 | W66: 0 | X66: 0 | Y66: 0 | Z66: 47759.554 | AA66: 0
A67: 55 | B67: 55 | G67: All | H67: =Setup!F63 -> 43850 | I67: 3879.5198 | J67: 2713.9298 | K67: 0 | L67: 16767.845 | M67: 0 | N67: 0 | O67: 0 | P67: 0 | Q67: 0 | R67: 924.9265 | S67: 47622.358 | T67: 0 | U67: 0 | V67: 0 | W67: 0 | X67: 0 | Y67: 0 | Z67: 43278.574 | AA67: 0
A68: 56 | B68: 56 | G68: All | H68: =Setup!F64 -> 43857 | I68: 3401.171 | J68: 2379.2994 | K68: 0 | L68: 17285.893 | M68: 0 | N68: 0 | O68: 0 | P68: 0 | Q68: 0 | R68: 6895.117 | S68: 194419.62 | T68: 0 | U68: 0 | V68: 0 | W68: 0 | X68: 0 | Y68: 0 | Z68: 41096.423 | AA68: 0
A69: 57 | B69: 57 | G69: All | H69: =Setup!F65 -> 43864 | I69: 3692.0456 | J69: 2582.7816 | K69: 3280.8947 | L69: 12631.614 | M69: 1699.0169 | N69: 0 | O69: 0 | P69: 0 | Q69: 0 | R69: 25323.002 | S69: 0 | T69: 0 | U69: 0 | V69: 0 | W69: 173956.54 | X69: 0 | Y69: 56409.835 | Z69: 42225.593 | AA69: 0
A70: 58 | B70: 58 | G70: All | H70: =Setup!F66 -> 43871 | I70: 2873.8196 | J70: 2010.3891 | K70: 5042.7713 | L70: 11518.643 | M70: 7138.0945 | N70: 0 | O70: 0 | P70: 0 | Q70: 0 | R70: 41813.275 | S70: 74459.019 | T70: 0 | U70: 0 | V70: 0 | W70: 173956.54 | X70: 0 | Y70: 70190.104 | Z70: 43195.055 | AA70: 0
A71: 59 | B71: 59 | G71: All | H71: =Setup!F67 -> 43878 | I71: 3321.5881 | J71: 2323.627 | K71: 13874.948 | L71: 12049.916 | M71: 10352.66 | N71: 0 | O71: 0 | P71: 0 | Q71: 0 | R71: 22024.539 | S71: 82977.567 | T71: 0 | U71: 0 | V71: 0 | W71: 0 | X71: 0 | Y71: 80445.444 | Z71: 35687.742 | AA71: 0
A72: 60 | B72: 60 | G72: All | H72: =Setup!F68 -> 43885 | I72: 3159.3871 | J72: 2210.1588 | K72: 2816.2625 | L72: 12759.626 | M72: 10729.308 | N72: 0 | O72: 0 | P72: 0 | Q72: 0 | R72: 22047.154 | S72: 0 | T72: 0 | U72: 0 | V72: 0 | W72: 0 | X72: 0 | Y72: 10512.471 | Z72: 31754.109 | AA72: 0
A73: 61 | B73: 61 | G73: All | H73: =Setup!F69 -> 43892 | I73: 3441.1021 | J73: 2407.2334 | K73: 5329.514 | L73: 10157.767 | M73: 14190.039 | N73: 0 | O73: 0 | P73: 0 | Q73: 0 | R73: 1002.936 | S73: 0 | T73: 0 | U73: 0 | V73: 0 | W73: 0 | X73: 0 | Y73: 30111.177 | Z73: 26234.538 | AA73: 0
A74: 62 | B74: 62 | G74: All | H74: =Setup!F70 -> 43899 | I74: 2876.835 | J74: 2012.4986 | K74: 6256.9761 | L74: 10244.889 | M74: 9009.7412 | N74: 0 | O74: 0 | P74: 0 | Q74: 0 | R74: 1002.9334 | S74: 0 | T74: 0 | U74: 0 | V74: 0 | W74: 0 | X74: 0 | Y74: 32698.947 | Z74: 36036.609 | AA74: 0
A75: 63 | B75: 63 | G75: All | H75: =Setup!F71 -> 43906 | I75: 3886.4006 | J75: 2718.7432 | K75: 5432.9177 | L75: 10441.4 | M75: 9015.1283 | N75: 0 | O75: 0 | P75: 0 | Q75: 0 | R75: 1002.9303 | S75: 0 | T75: 0 | U75: 0 | V75: 0 | W75: 0 | X75: 0 | Y75: 32972.72 | Z75: 30266.594 | AA75: 0
A76: 64 | B76: 64 | G76: All | H76: =Setup!F72 -> 43913 | I76: 2409.7926 | J76: 1685.7777 | K76: 555.63082 | L76: 5212.6542 | M76: 1122.8178 | N76: 0 | O76: 0 | P76: 0 | Q76: 0 | R76: 1002.9288 | S76: 254695.43 | T76: 0 | U76: 0 | V76: 0 | W76: 0 | X76: 0 | Y76: 9046.1023 | Z76: 12167.208 | AA76: 0
... A94: 82 | B94: 82 | G94: All | H94: =Setup!F90 -> 44039 | I94: 3090.8172 | J94: 2162.1905 | K94: 13939.361 | L94: 5155.5444 | M94: 1710.5082 | N94: 0 | O94: 0 | P94: 0 | Q94: 0 | R94: 0 | S94: 0 | T94: 0 | U94: 4402.2257 | V94: 0 | W94: 0 | X94: 0 | Y94: 62524.421 | Z94: 15273.504 | AA94: 0
A95: 83 | B95: 83 | C95: 83 | G95: All | H95: =Setup!F91 -> 44046 | I95: 8016.4236 | J95: 5607.9133 | K95: 19421.969 | L95: 11166.388 | M95: 2131.2665 | N95: 0 | O95: 147090.57 | P95: 0 | Q95: 0 | R95: 0 | S95: 0 | T95: 0 | U95: 7159.1584 | V95: 0 | W95: 0 | X95: 0 | Y95: 224059.49 | Z95: 24709.953 | AA95: 26250
A96: 84 | B96: 84 | C96: 84 | G96: All | H96: =Setup!F92 -> 44053 | I96: 9597.198 | J96: 6713.7488 | K96: 28691.575 | L96: 13657.3 | M96: 4885.8742 | N96: 0 | O96: 147090.57 | P96: 0 | Q96: 0 | R96: 0 | S96: 0 | T96: 0 | U96: 0 | V96: 0 | W96: 0 | X96: 0 | Y96: 293285.14 | Z96: 34967.096 | AA96: 26250
...

Sheet Dictionary
C3: Data Table: feat | E3: =IF(ISERROR(SUM(feat[Match])),"Missing Group 1 in dict","No gaps") -> No gaps | J3: Data Table: dict
C4: Feature | D4: Group 1 | E4: Match | F4: Prism Code | J4: Group 1 | K4: Group 2 | L4: Group 3 | M4: Group 4
C5: sales | D5: Sales | E5: =MATCH(feat[[#This Row],[Group 1]],dict[Group 1],0) -> 1 | F5: =CONCATENATE("'",feat[[#This Row],[Feature]],"': {},") -> 'sales': {}, | J5: Sales | K5: Sales | L5: Sales | M5: Sales
C6: vday_dummy | D6: Seasonality | E6: =MATCH(feat[[#This Row],[Group 1]],dict[Group 1],0) -> 2 | F6: =CONCATENATE("'",feat[[#This Row],[Feature]],"': {},") -> 'vday_dummy': {}, | J6: Seasonality | K6: Macro | L6: Macro | M6: Macro
C7: blackfriday_dummy | D7: Seasonality | E7: =MATCH(feat[[#This Row],[Group 1]],dict[Group 1],0) -> 2 | F7: =CONCATENATE("'",feat[[#This Row],[Feature]],"': {},") -> 'blackfriday_dummy': {}, | J7: Market | K7: Macro | L7: Macro | M7: Macro
C8: mothersday_dummy | D8: Seasonality | E8: =MATCH(feat[[#This Row],[Group 1]],dict[Group 1],0) -> 2 | F8: =CONCATENATE("'",feat[[#This Row],[Feature]],"': {},") -> 'mothersday_dummy': {}, | J8: Covid | K8: Covid | L8: Covid | M8: Macro
C9: xmas_dummy | D9: Seasonality | E9: =MATCH(feat[[#This Row],[Group 1]],dict[Group 1],0) -> 2 | F9: =CONCATENATE("'",feat[[#This Row],[Feature]],"': {},") -> 'xmas_dummy': {}, | J9: Product Launch | K9: Product Launch | L9: Promotion | M9: Promotion
C10: market_sales | D10: Market | E10: =MATCH(feat[[#This Row],[Group 1]],dict[Group 1],0) -> 3 | F10: =CONCATENATE("'",feat[[#This Row],[Feature]],"': {},") -> 'market_sales': {}, | J10: GWP | K10: GWP | L10: Promotion | M10: Promotion
C11: covid_trend | D11: Covid | E11: =MATCH(feat[[#This Row],[Group 1]],dict[Group 1],0) -> 4 | F11: =CONCATENATE("'",feat[[#This Row],[Feature]],"': {},") -> 'covid_trend': {}, | J11: Samples | K11: Samples | L11: Promotion | M11: Promotion
C12: launch_fragrance_trend | D12: Product Launch | E12: =MATCH(feat[[#This Row],[Group 1]],dict[Group 1],0) -> 5 | F12: =CONCATENATE("'",feat[[#This Row],[Feature]],"': {},") -> 'launch_fragrance_trend': {}, | J12: TV - Pure | K12: TV | L12: Traditional Media | M12: Media
C13: launch_makeup_trend | D13: Product Launch | E13: =MATCH(feat[[#This Row],[Group 1]],dict[Group 1],0) -> 5 | F13: =CONCATENATE("'",feat[[#This Row],[Feature]],"': {},") -> 'launch_makeup_trend': {}, | J13: TV - Coop | K13: TV | L13: Traditional Media | M13: Media
C14: launch_skincare_trend | D14: Product Launch | E14: =MATCH(feat[[#This Row],[Group 1]],dict[Group 1],0) -> 5 | F14: =CONCATENATE("'",feat[[#This Row],[Feature]],"': {},") -> 'launch_skincare_trend': {}, | J14: Print - Pure | K14: Print | L14: Traditional Media | M14: Media
C15: gwp_units_distributed | D15: GWP | E15: =MATCH(feat[[#This Row],[Group 1]],dict[Group 1],0) -> 6 | F15: =CONCATENATE("'",feat[[#This Row],[Feature]],"': {},") -> 'gwp_units_distributed': {}, | J15: Print - Coop | K15: Print | L15: Traditional Media | M15: Media
C16: samples_quantity_distributed | D16: Samples | E16: =MATCH(feat[[#This Row],[Group 1]],dict[Group 1],0) -> 7 | F16: =CONCATENATE("'",feat[[#This Row],[Feature]],"': {},") -> 'samples_quantity_distributed': {}, | J16: Outdoor | K16: Outdoor | L16: Traditional Media | M16: Media
... C24: google_brand_search_clicks | D24: Search - Brand | E24: =MATCH(feat[[#This Row],[Group 1]],dict[Group 1],0) -> 13 | F24: =CONCATENATE("'",feat[[#This Row],[Feature]],"': {},") -> 'google_brand_search_clicks': {}, | J24: Display | K24: Display | L24: Digital Media | M24: Media
C25: google_brand_search_imp | D25: Search - Brand | E25: =MATCH(feat[[#This Row],[Group 1]],dict[Group 1],0) -> 13 | F25: =CONCATENATE("'",feat[[#This Row],[Feature]],"': {},") -> 'google_brand_search_imp': {},
C26: google_brand_search_spend | D26: Search - Brand | E26: =MATCH(feat[[#This Row],[Group 1]],dict[Group 1],0) -> 13 | F26: =CONCATENATE("'",feat[[#This Row],[Feature]],"': {},") -> 'google_brand_search_spend': {},
C27: google_nonbrand_search_clicks | D27: Search - Non-Brand | E27: =MATCH(feat[[#This Row],[Group 1]],dict[Group 1],0) -> 14 | F27: =CONCATENATE("'",feat[[#This Row],[Feature]],"': {},") -> 'google_nonbrand_search_clicks': {},
C28: google_nonbrand_search_imp | D28: Search - Non-Brand | E28: =MATCH(feat[[#This Row],[Group 1]],dict[Group 1],0) -> 14 | F28: =CONCATENATE("'",feat[[#This Row],[Feature]],"': {},") -> 'google_nonbrand_search_imp': {},
C29: google_nonbrand_search_spend | D29: Search - Non-Brand | E29: =MATCH(feat[[#This Row],[Group 1]],dict[Group 1],0) -> 14 | F29: =CONCATENATE("'",feat[[#This Row],[Feature]],"': {},") -> 'google_nonbrand_search_spend': {},
C30: bing_brand_search_clicks | D30: Search - Brand | E30: =MATCH(feat[[#This Row],[Group 1]],dict[Group 1],0) -> 13 | F30: =CONCATENATE("'",feat[[#This Row],[Feature]],"': {},") -> 'bing_brand_search_clicks': {},
C31: bing_brand_search_spend | D31: Search - Brand | E31: =MATCH(feat[[#This Row],[Group 1]],dict[Group 1],0) -> 13 | F31: =CONCATENATE("'",feat[[#This Row],[Feature]],"': {},") -> 'bing_brand_search_spend': {},
C32: pinterest_awareness_imp | D32: Pinterest | E32: =MATCH(feat[[#This Row],[Group 1]],dict[Group 1],0) -> 15 | F32: =CONCATENATE("'",feat[[#This Row],[Feature]],"': {},") -> 'pinterest_awareness_imp': {},
C33: pinterest_awareness_spend | D33: Pinterest | E33: =MATCH(feat[[#This Row],[Group 1]],dict[Group 1],0) -> 15 | F33: =CONCATENATE("'",feat[[#This Row],[Feature]],"': {},") -> 'pinterest_awareness_spend': {},
C34: pinterest_conversion_imp | D34: Pinterest | E34: =MATCH(feat[[#This Row],[Group 1]],dict[Group 1],0) -> 15 | F34: =CONCATENATE("'",feat[[#This Row],[Feature]],"': {},") -> 'pinterest_conversion_imp': {},
C35: pinterest_conversion_spend | D35: Pinterest | E35: =MATCH(feat[[#This Row],[Group 1]],dict[Group 1],0) -> 15 | F35: =CONCATENATE("'",feat[[#This Row],[Feature]],"': {},") -> 'pinterest_conversion_spend': {},
C36: snap_awareness_imp | D36: Snapchat | E36: =MATCH(feat[[#This Row],[Group 1]],dict[Group 1],0) -> 16 | F36: =CONCATENATE("'",feat[[#This Row],[Feature]],"': {},") -> 'snap_awareness_imp': {},
... C67: type_in_name_of_new_seasonality_variable | D67: Seasonality | E67: =MATCH(feat[[#This Row],[Group 1]],dict[Group 1],0) -> 2 | F67: =CONCATENATE("'",feat[[#This Row],[Feature]],"': {},") -> 'type_in_name_of_new_seasonality_variable': {},

Sheet InputSheet
B1: Data Rows
B2: =COUNTA(E:E) -> 109 | D2: Clear table before pasting in! | F2: {=OFFSET($E3,0,1,1,$B$4)&TEXT(OFFSET($E4,0,1,1,$B$4)," +L0;;;")&TEXT(OFFSET($E5,0,1,1,$B$4)*100," +A0;;;")&TEXT(OFFSET($E6,0,1,1,$B$4)+OFFSET($E7,0,1,1,$B$4)," +""S""0.0;;;")} -> sales | G2: bing_brand_search_clicks | H2: bing_brand_search_spend | I2: blackfriday_dummy | J2: covid_trend | K2: google_brand_search_clicks | L2: google_brand_search_imp | M2: google_brand_search_spend | N2: google_display_clicks | O2: google_display_imp | P2: google_display_spend | Q2: google_nonbrand_search_clicks | R2: google_nonbrand_search_imp | S2: google_nonbrand_search_spend | T2: google_video_clicks | U2: google_video_imp | V2: google_video_spend | W2: gwp_units_distributed | X2: launch_fragrance_trend | Y2: launch_makeup_trend | Z2: launch_skincare_trend | AA2: market_sales | AB2: mothersday_dummy | AC2: nongoogle_display_spend | AD2: nongoogle_video_spend | AE2: pinterest_awareness_imp | AF2: pinterest_awareness_spend | AG2: pinterest_conversion_imp | AH2: pinterest_conversion_spend | AI2: print_coop_spend | AJ2: print_pure_spend | AK2: samples_quantity_distributed | AL2: snap_awareness_imp | AM2: snap_awareness_spend | AN2: snap_conversion_imp | AO2: snap_conversion_spend | AP2: tiktok_awareness_imp | AQ2: tiktok_awareness_spend | AR2: tv_coop_spend | AS2: tv_pure_imp | AT2: tv_pure_spend +L1 | AU2: vday_dummy | AV2: xmas_dummy | AW2: youtube_video_spend | AX2: fbig_spend | AY2: fbig_imp +A60 | AZ2: youtube_video_imp | BA2: outdoor_impressions +A20 | BB2: outdoor_spend | BC2: covid_holiday_period | BD2: covid_xmas | BE2: tv_coop_spend_after_2020-04-13 | BF2: print_pure_spend_after_2020-04-13 +L1 | BG2: print_pure_spend_before_2020-04-13 | BH2: total_product_launch | BI2: week_before_laborday | BJ2: week_before_vday +A30 | BK2: july_promo | BL2: mothersday_2019 | BM2: blackfriday_2019 | BN2: friends_and_family_august_promo | BO2: flash_sale_promo | BP2: new_year
B3: Data Cols | D3: Paste Here | E3: date | F3: sales | G3: bing_brand_search_clicks | H3: bing_brand_search_spend | I3: blackfriday_dummy | J3: covid_trend | K3: google_brand_search_clicks | L3: google_brand_search_imp | M3: google_brand_search_spend | N3: google_display_clicks | O3: google_display_imp | P3: google_display_spend | Q3: google_nonbrand_search_clicks | R3: google_nonbrand_search_imp | S3: google_nonbrand_search_spend | T3: google_video_clicks | U3: google_video_imp | V3: google_video_spend | W3: gwp_units_distributed | X3: launch_fragrance_trend | Y3: launch_makeup_trend | Z3: launch_skincare_trend | AA3: market_sales | AB3: mothersday_dummy | AC3: nongoogle_display_spend | AD3: nongoogle_video_spend | AE3: pinterest_awareness_imp | AF3: pinterest_awareness_spend | AG3: pinterest_conversion_imp | AH3: pinterest_conversion_spend | AI3: print_coop_spend | AJ3: print_pure_spend | AK3: samples_quantity_distributed | AL3: snap_awareness_imp | AM3: snap_awareness_spend | AN3: snap_conversion_imp | AO3: snap_conversion_spend | AP3: tiktok_awareness_imp | AQ3: tiktok_awareness_spend | AR3: tv_coop_spend | AS3: tv_pure_imp | AT3: tv_pure_spend | AU3: vday_dummy | AV3: xmas_dummy | AW3: youtube_video_spend | AX3: fbig_spend | AY3: fbig_imp | AZ3: youtube_video_imp | BA3: outdoor_impressions | BB3: outdoor_spend | BC3: covid_holiday_period | BD3: covid_xmas | BE3: tv_coop_spend_after_2020-04-13 | BF3: print_pure_spend_after_2020-04-13 | BG3: print_pure_spend_before_2020-04-13 | BH3: total_product_launch | BI3: week_before_laborday | BJ3: week_before_vday | BK3: july_promo | BL3: mothersday_2019 | BM3: blackfriday_2019 | BN3: friends_and_family_august_promo | BO3: flash_sale_promo | BP3: new_year
B4: =COUNTA(3:3)-COUNTA(A3:E3) -> 63 | E4: lag | G4: 0 | J4: 0 | L4: 0 | O4: 0 | R4: 0 | U4: 0 | W4: 0 | AA4: 0 | AC4: 0 | AD4: 0 | AE4: 0 | AG4: 0 | AI4: 0 | AK4: 0 | AL4: 0 | AN4: 0 | AR4: 0 | AT4: 1 | AV4: 0 | AY4: 0 | AZ4: 0 | BA4: 0 | BC4: 0 | BD4: 0 | BE4: 0 | BF4: 1 | BG4: 0 | BH4: 0 | BJ4: 0 | BK4: 0 | BL4: 0 | BM4: 0 | BN4: 0 | BO4: 0 | BP4: 0
E5: adstock | G5: 0 | J5: 0 | L5: 0 | O5: 0 | R5: 0 | U5: 0 | W5: 0 | AA5: 0 | AC5: 0 | AD5: 0 | AE5: 0 | AG5: 0 | AI5: 0 | AK5: 0 | AL5: 0 | AN5: 0 | AR5: 0 | AT5: 0 | AV5: 0 | AY5: 0.6 | AZ5: 0 | BA5: 0.2 | BC5: 0 | BD5: 0 | BE5: 0 | BF5: 0 | BG5: 0 | BH5: 0 | BJ5: 0.3 | BK5: 0 | BL5: 0 | BM5: 0 | BN5: 0 | BO5: 0 | BP5: 0
B6: =Setup!B6 -> All | E6: saturation_K
B7: Filter | D7: province_cat | E7: saturation_S
B8: {=IFERROR(SEARCH($B$6,OFFSET($D$7,1,0,$B$2,1)),0)} -> 1 | D8: All | E8: 43472 | F8: 6096762.5 | G8: 2900.8768 | H8: 8535.213 | I8: 0 | J8: 0 | K8: 6445.1076 | L8: 225599.02 | M8: 5970.834 | N8: 192.45043 | O8: 72160.543 | P8: 385.81377 | Q8: 8048.5676 | R8: 301929.62 | S8: 19863.905 | T8: 417.48972 | U8: 123341.35 | V8: 1587.0688 | W8: 21235 | X8: 0 | Y8: 0.65777462 | Z8: 0 | AA8: 2.4461557e+08 | AB8: 0 | AC8: 0 | AD8: 0 | AE8: 0 | AF8: 0 | AG8: 0 | AH8: 0 | AI8: 291.8426 | AJ8: 68696.88 | AK8: 285111 | AL8: 0 | AM8: 0 | AN8: 0 | AO8: 0 | AP8: 0 | AQ8: 0 | AR8: 0 | AS8: 0 | AT8: 0 | AU8: 0 | AV8: 0 | AW8: 6008.7616 | AX8: 0 | AY8: 0 | AZ8: 532627.15 | BA8: 0 | BB8: 0 | BC8: 0 | BD8: 0 | BE8: 0 | BF8: 0 | BG8: 68696.88 | BH8: 0.65777462 | BI8: 0 | BJ8: 0 | BK8: 0 | BL8: 0 | BM8: 0 | BN8: 0 | BO8: 0 | BP8: 0
B9: 1 | D9: All | E9: 43479 | F9: 6089210.2 | G9: 2256.867 | H9: 7213.1737 | I9: 0 | J9: 0 | K9: 5744.4471 | L9: 207751.34 | M9: 5045.9974 | N9: 77.508639 | O9: 34493.547 | P9: 193.1763 | Q9: 7100.4079 | R9: 270855.26 | S9: 17575.176 | T9: 503.80616 | U9: 150301.58 | V9: 1892.74 | W9: 0 | X9: 0.038621946 | Y9: 0.46331831 | Z9: 0 | AA9: 2.5259263e+08 | AB9: 0 | AC9: 0 | AD9: 0 | AE9: 0 | AF9: 0 | AG9: 0 | AH9: 0 | AI9: 291.84229 | AJ9: 128080.38 | AK9: 489603 | AL9: 0 | AM9: 0 | AN9: 0 | AO9: 0 | AP9: 0 | AQ9: 0 | AR9: 0 | AS9: 0 | AT9: 0 | AU9: 0 | AV9: 0 | AW9: 4042.4816 | AX9: 0 | AY9: 0 | AZ9: 363528.09 | BA9: 0 | BB9: 0 | BC9: 0 | BD9: 0 | BE9: 0 | BF9: 0 | BG9: 128080.38 | BH9: 0.50194025 | BI9: 0 | BJ9: 0 | BK9: 0 | BL9: 0 | BM9: 0 | BN9: 0 | BO9: 0 | BP9: 0
B10: 1 | D10: All | E10: 43486 | F10: 6508506.8 | G10: 834.12798 | H10: 7174.7345 | I10: 0 | J10: 0 | K10: 5925.4474 | L10: 211989.21 | M10: 5019.1072 | N10: 188.92731 | O10: 84085.864 | P10: 459.46324 | Q10: 4985.6552 | R10: 198156.12 | S10: 12181.654 | T10: 413.08582 | U10: 135798.22 | V10: 1711.4357 | W10: 0 | X10: 0.22152892 | Y10: 0.37955382 | Z10: 0 | AA10: 2.5558166e+08 | AB10: 0 | AC10: 0 | AD10: 0 | AE10: 0 | AF10: 0 | AG10: 0 | AH10: 0 | AI10: 291.84168 | AJ10: 138871.58 | AK10: 302329 | AL10: 0 | AM10: 0 | AN10: 0 | AO10: 0 | AP10: 0 | AQ10: 0 | AR10: 0 | AS10: 0 | AT10: 0 | AU10: 0 | AV10: 0 | AW10: 3810.1154 | AX10: 0 | AY10: 0 | AZ10: 355039.52 | BA10: 0 | BB10: 0 | BC10: 0 | BD10: 0 | BE10: 0 | BF10: 0 | BG10: 138871.58 | BH10: 0.60108275 | BI10: 0 | BJ10: 0 | BK10: 0 | BL10: 0 | BM10: 0 | BN10: 0 | BO10: 0 | BP10: 0
B11: 1 | D11: All | E11: 43493 | F11: 7022937.1 | G11: 1875.3715 | H11: 7815.4707 | I11: 0 | J11: 0 | K11: 6411.1976 | L11: 261913.14 | M11: 5467.3361 | N11: 221.07578 | O11: 103102.34 | P11: 552.38057 | Q11: 5072.412 | R11: 193075.78 | S11: 12393.209 | T11: 726.20311 | U11: 313427.32 | V11: 3413.5203 | W11: 0 | X11: 0.023616164 | Y11: 0 | Z11: 0 | AA11: 2.4766957e+08 | AB11: 0 | AC11: 0 | AD11: 0 | AE11: 0 | AF11: 0 | AG11: 0 | AH11: 0 | AI11: 13837.331 | AJ11: 0 | AK11: 371304 | AL11: 0 | AM11: 0 | AN11: 0 | AO11: 0 | AP11: 0 | AQ11: 0 | AR11: 0 | AS11: 0 | AT11: 0 | AU11: 0 | AV11: 0 | AW11: 7283.5619 | AX11: 0 | AY11: 0 | AZ11: 596112.99 | BA11: 0 | BB11: 0 | BC11: 0 | BD11: 0 | BE11: 0 | BF11: 0 | BG11: 0 | BH11: 0.023616164 | BI11: 0 | BJ11: 0 | BK11: 0 | BL11: 0 | BM11: 0 | BN11: 0 | BO11: 0 | BP11: 0
B12: 1 | D12: All | E12: 43500 | F12: 19633183 | G12: 2128.4428 | H12: 9028.5069 | I12: 0 | J12: 0 | K12: 7195.5322 | L12: 283329.31 | M12: 6315.9192 | N12: 1185.5299 | O12: 1881717.3 | P12: 6625.4674 | Q12: 6423.0881 | R12: 227563.16 | S12: 15256.219 | T12: 1536.9611 | U12: 1156974.1 | V12: 10973.407 | W12: 0 | X12: 0.032639321 | Y12: 0.00132715 | Z12: 0 | AA12: 3.0204759e+08 | AB12: 0 | AC12: 0 | AD12: 0 | AE12: 0 | AF12: 0 | AG12: 0 | AH12: 0 | AI12: 31897.984 | AJ12: 102556.37 | AK12: 468574 | AL12: 0 | AM12: 0 | AN12: 0 | AO12: 0 | AP12: 0 | AQ12: 0 | AR12: 191864.99 | AS12: 0 | AT12: 0 | AU12: 0 | AV12: 0 | AW12: 25594.411 | AX12: 0 | AY12: 0 | AZ12: 2251435 | BA12: 0 | BB12: 0 | BC12: 0 | BD12: 0 | BE12: 0 | BF12: 0 | BG12: 102556.37 | BH12: 0.033966471 | BI12: 0 | BJ12: 1 | BK12: 0 | BL12: 0 | BM12: 0 | BN12: 0 | BO12: 0 | BP12: 0
B13: 1 | D13: All | E13: 43507 | F13: 12143474 | G13: 2207.1341 | H13: 9331.1159 | I13: 0 | J13: 0 | K13: 6759.9865 | L13: 293126.22 | M13: 6527.6103 | N13: 2989.8077 | O13: 5153010.8 | P13: 17620.744 | Q13: 6428.8132 | R13: 230271.56 | S13: 15424.668 | T13: 1894.1174 | U13: 1818067.3 | V13: 17235.529 | W13: 0 | X13: 0 | Y13: 0.041399347 | Z13: 0.00070642 | AA13: 3.4458308e+08 | AB13: 0 | AC13: 0 | AD13: 0 | AE13: 0 | AF13: 0 | AG13: 0 | AH13: 0 | AI13: 30455.078 | AJ13: 0 | AK13: 208336 | AL13: 0 | AM13: 0 | AN13: 0 | AO13: 0 | AP13: 0 | AQ13: 0 | AR13: 191864.99 | AS13: 0 | AT13: 0 | AU13: 1 | AV13: 0 | AW13: 28391.391 | AX13: 0 | AY13: 0 | AZ13: 2549329 | BA13: 0 | BB13: 0 | BC13: 0 | BD13: 0 | BE13: 0 | BF13: 0 | BG13: 0 | BH13: 0.042105767 | BI13: 0 | BJ13: 0.3 | BK13: 0 | BL13: 0 | BM13: 0 | BN13: 0 | BO13: 0 | BP13: 0
B14: 1 | D14: All | E14: 43514 | F14: 9691781.5 | G14: 1704.7687 | H14: 7430.1603 | I14: 0 | J14: 0 | K14: 4640.8298 | L14: 161760.09 | M14: 5197.791 | N14: 1134.885 | O14: 1994596.3 | P14: 7583.5941 | Q14: 6520.8547 | R14: 239695.47 | S14: 15136.64 | T14: 1014.2182 | U14: 1171058.2 | V14: 10726.01 | W14: 0 | X14: 0 | Y14: 0.019437 | Z14: 0.042161779 | AA14: 2.956075e+08 | AB14: 0 | AC14: 0 | AD14: 0 | AE14: 0 | AF14: 0 | AG14: 0 | AH14: 0 | AI14: 12580.871 | AJ14: 172271.21 | AK14: 829297 | AL14: 0 | AM14: 0 | AN14: 0 | AO14: 0 | AP14: 0 | AQ14: 0 | AR14: 191864.99 | AS14: 0 | AT14: 0 | AU14: 0 | AV14: 0 | AW14: 12064.529 | AX14: 0 | AY14: 0 | AZ14: 1120416 | BA14: 0 | BB14: 0 | BC14: 0 | BD14: 0 | BE14: 0 | BF14: 0 | BG14: 172271.21 | BH14: 0.061598779 | BI14: 0 | BJ14: 0.09 | BK14: 0 | BL14: 0 | BM14: 0 | BN14: 0 | BO14: 0 | BP14: 0
B15: 1 | D15: All | E15: 43521 | F15: 7689159.6 | G15: 1597.7485 | H15: 6198.8048 | I15: 0 | J15: 0 | K15: 3826.9891 | L15: 93100.647 | M15: 4336.3926 | N15: 1394.2747 | O15: 2431316.5 | P15: 8957.4623 | Q15: 5998.9925 | R15: 229529.06 | S15: 13790.822 | T15: 881.66077 | U15: 652310.07 | V15: 6222.9989 | W15: 0 | X15: 0.25167989 | Y15: 0.0025707 | Z15: 0.054890715 | AA15: 2.9142605e+08 | AB15: 0 | AC15: 0 | AD15: 0 | AE15: 0 | AF15: 0 | AG15: 0 | AH15: 0 | AI15: 13242.876 | AJ15: 0 | AK15: 712828 | AL15: 0 | AM15: 0 | AN15: 0 | AO15: 0 | AP15: 0 | AQ15: 0 | AR15: 0 | AS15: 0 | AT15: 0 | AU15: 0 | AV15: 0 | AW15: 9795.5138 | AX15: 0 | AY15: 0 | AZ15: 901653.7 | BA15: 0 | BB15: 0 | BC15: 0 | BD15: 0 | BE15: 0 | BF15: 0 | BG15: 0 | BH15: 0.3091413 | BI15: 0 | BJ15: 0.027 | BK15: 0 | BL15: 0 | BM15: 0 | BN15: 0 | BO15: 0 | BP15: 0
B16: 1 | D16: All | E16: 43528 | F16: 10234522 | G16: 1814.3071 | H16: 7126.8902 | I16: 0 | J16: 0 | K16: 4476.5643 | L16: 171533.23 | M16: 4985.6375 | N16: 1411.4499 | O16: 2262162.7 | P16: 8559.8125 | Q16: 5557.2814 | R16: 184579.78 | S16: 13539.399 | T16: 1532.5572 | U16: 1031359.9 | V16: 9866.5972 | W16: 185897 | X16: 2.5620533 | Y16: 0.0069388 | Z16: 0.10726779 | AA16: 3.314311e+08 | AB16: 0 | AC16: 0 | AD16: 0 | AE16: 0 | AF16: 0 | AG16: 0 | AH16: 0 | AI16: 31621.187 | AJ16: 0 | AK16: 673603 | AL16: 0 | AM16: 0 | AN16: 0 | AO16: 0 | AP16: 0 | AQ16: 0 | AR16: 28401.068 | AS16: 0 | AT16: 0 | AU16: 0 | AV16: 0 | AW16: 9919.1396 | AX16: 0 | AY16: 0 | AZ16: 885470.61 | BA16: 0 | BB16: 0 | BC16: 0 | BD16: 0 | BE16: 0 | BF16: 0 | BG16: 0 | BH16: 2.6762598 | BI16: 0 | BJ16: 0 | BK16: 0 | BL16: 0 | BM16: 0 | BN16: 0 | BO16: 0 | BP16: 0
B17: 1 | D17: All | E17: 43535 | F17: 9309029.2 | G17: 1716.1003 | H17: 9041.1667 | I17: 0 | J17: 0 | K17: 5948.3477 | L17: 275232.3 | M17: 6324.7754 | N17: 1650.1413 | O17: 2892995.4 | P17: 11191.914 | Q17: 5203.6482 | R17: 171564.93 | S17: 12826.262 | T17: 1916.5773 | U17: 1238496 | V17: 12756.787 | W17: 100412 | X17: 6.1382 | Y17: 0.033388586 | Z17: 1.0504388 | AA17: 3.1302486e+08 | AB17: 0 | AC17: 0 | AD17: 0 | AE17: 0 | AF17: 0 | AG17: 0 | AH17: 0 | AI17: 31806.192 | AJ17: 124936.11 | AK17: 262005 | AL17: 0 | AM17: 0 | AN17: 0 | AO17: 0 | AP17: 0 | AQ17: 0 | AR17: 28401.068 | AS17: 0 | AT17: 0 | AU17: 0 | AV17: 0 | AW17: 13554.999 | AX17: 0 | AY17: 0 | AZ17: 1072549.2 | BA17: 0 | BB17: 0 | BC17: 0 | BD17: 0 | BE17: 0 | BF17: 0 | BG17: 124936.11 | BH17: 7.2220274 | BI17: 0 | BJ17: 0 | BK17: 0 | BL17: 0 | BM17: 0 | BN17: 0 | BO17: 0 | BP17: 0
B18: 1 | D18: All | E18: 43542 | F18: 12102723 | G18: 1461.1404 | H18: 9687.5569 | I18: 0 | J18: 0 | K18: 6383.0126 | L18: 302482.75 | M18: 6776.9596 | N18: 2128.4049 | O18: 3771744.4 | P18: 14381.077 | Q18: 4656.6838 | R18: 160591.3 | S18: 11685.269 | T18: 1142.812 | U18: 950705.56 | V18: 9198.0748 | W18: 3528 | X18: 13.436133 | Y18: 0.0099693 | Z18: 1.5849695 | AA18: 3.7821918e+08 | AB18: 0 | AC18: 0 | AD18: 0 | AE18: 0 | AF18: 0 | AG18: 365287.89 | AH18: 1466.832 | AI18: 1587.1126 | AJ18: 0 | AK18: 449101 | AL18: 0 | AM18: 0 | AN18: 0 | AO18: 0 | AP18: 0 | AQ18: 0 | AR18: 28401.068 | AS18: 0 | AT18: 0 | AU18: 0 | AV18: 0 | AW18: 19186.103 | AX18: 0 | AY18: 0 | AZ18: 1485778.8 | BA18: 0 | BB18: 0 | BC18: 0 | BD18: 0 | BE18: 0 | BF18: 0 | BG18: 0 | BH18: 15.031072 | BI18: 0 | BJ18: 0 | BK18: 0 | BL18: 0 | BM18: 0 | BN18: 0 | BO18: 1 | BP18: 0
B19: 1 | D19: All | E19: 43549 | F19: 9283960.8 | G19: 1592.7123 | H19: 6094.4152 | I19: 0 | J19: 0 | K19: 4669.4551 | L19: 194113.78 | M19: 4263.3665 | N19: 1909.0906 | O19: 3270127.8 | P19: 13680.062 | Q19: 5093.1103 | R19: 174979.28 | S19: 13208.833 | T19: 995.28139 | U19: 646405.32 | V19: 6776.7154 | W19: 0 | X19: 10.22844 | Y19: 0.033977548 | Z19: 2.3107328 | AA19: 3.5580621e+08 | AB19: 0 | AC19: 0 | AD19: 0 | AE19: 0 | AF19: 0 | AG19: 1213088.5 | AH19: 5663.8375 | AI19: 476.88065 | AJ19: 346712.64 | AK19: 632548 | AL19: 0 | AM19: 0 | AN19: 0 | AO19: 0 | AP19: 0 | AQ19: 0 | AR19: 0 | AS19: 0 | AT19: 0 | AU19: 0 | AV19: 0 | AW19: 17619.136 | AX19: 0 | AY19: 0 | AZ19: 1261825.2 | BA19: 0 | BB19: 0 | BC19: 0 | BD19: 0 | BE19: 0 | BF19: 0 | BG19: 346712.64 | BH19: 12.57315 | BI19: 0 | BJ19: 0 | BK19: 0 | BL19: 0 | BM19: 0 | BN19: 0 | BO19: 0 | BP19: 0
B20: 1 | D20: All | E20: 43556 | F20: 8030813.2 | G20: 1411.4075 | H20: 5280.9621 | I20: 0 | J20: 0 | K20: 4353.6955 | L20: 208962.85 | M20: 3694.313 | N20: 804.15213 | O20: 932129.47 | P20: 4133.3607 | Q20: 5303.6167 | R20: 203297.67 | S20: 12834.149 | T20: 1772.5697 | U20: 477717.01 | V20: 5269.9098 | W20: 3000 | X20: 10.776179 | Y20: 0.48124695 | Z20: 3.3550964 | AA20: 3.0530716e+08 | AB20: 0 | AC20: 0 | AD20: 0 | AE20: 0 | AF20: 0 | AG20: 342759.83 | AH20: 1968.2189 | AI20: 12306.024 | AJ20: 0 | AK20: 367026 | AL20: 0 | AM20: 0 | AN20: 0 | AO20: 0 | AP20: 0 | AQ20: 0 | AR20: 59168.891 | AS20: 0 | AT20: 0 | AU20: 0 | AV20: 0 | AW20: 9911.1563 | AX20: 0 | AY20: 0 | AZ20: 776745.54 | BA20: 0 | BB20: 0 | BC20: 0 | BD20: 0 | BE20: 0 | BF20: 0 | BG20: 0 | BH20: 14.612522 | BI20: 0 | BJ20: 0 | BK20: 0 | BL20: 0 | BM20: 0 | BN20: 0 | BO20: 0 | BP20: 0
... B111: 1 | D111: All | E111: 44193 | F111: 5481824.2 | G111: 1677.6989 | H111: 16219.52 | I111: 0 | J111: -35.317458 | K111: 16333.625 | L111: 1173712.9 | M111: 11346.414 | N111: 15386.346 | O111: 8660576.7 | P111: 56061.991 | Q111: 8088.2027 | R111: 127000.99 | S111: 12319.752 | T111: 40.07549 | U111: 59596.657 | V111: 1072.7398 | W111: 1812 | X111: 17.748372 | Y111: 8.2164651 | Z111: 3.5181854 | AA111: 2.8733595e+08 | AB111: 0 | AC111: 0 | AD111: 0 | AE111: 626.16425 | AF111: 0 | AG111: 778984.46 | AH111: 3778.0326 | AI111: 0 | AJ111: 0 | AK111: 499268 | AL111: 172.72072 | AM111: 0 | AN111: 58.449217 | AO111: 0 | AP111: 2914031.3 | AQ111: 27056.96 | AR111: 0 | AS111: 0 | AT111: 0 | AU111: 0 | AV111: 0 | AW111: 39218.948 | AX111: 18749.434 | AY111: 20854669 | AZ111: 1939259.6 | BA111: 0 | BB111: 0 | BC111: 0 | BD111: 0 | BE111: 0 | BF111: 35426.906 | BG111: 0 | BH111: 29.483022 | BI111: 0 | BJ111: 0 | BK111: 0 | BL111: 0 | BM111: 0 | BN111: 0 | BO111: 0 | BP111: 0
B112: 0
B113: 0
B114: 0
B115: 0
B116: 0

Sheet IS
C2: Data R x C | D2: =ROWS(_xlfn.ANCHORARRAY(C5)) -> 104 | E2: =InputSheet!B4 -> 63
B4: Level | C4: Date | D4: {=_xlfn.ANCHORARRAY(InputSheet!F2)} -> sales | E4: bing_brand_search_clicks | F4: bing_brand_search_spend | G4: blackfriday_dummy | H4: covid_trend | I4: google_brand_search_clicks | J4: google_brand_search_imp | K4: google_brand_search_spend | L4: google_display_clicks | M4: google_display_imp | N4: google_display_spend | O4: google_nonbrand_search_clicks | P4: google_nonbrand_search_imp | Q4: google_nonbrand_search_spend | R4: google_video_clicks | S4: google_video_imp | T4: google_video_spend | U4: gwp_units_distributed | V4: launch_fragrance_trend | W4: launch_makeup_trend | X4: launch_skincare_trend | Y4: market_sales | Z4: mothersday_dummy | AA4: nongoogle_display_spend | AB4: nongoogle_video_spend | AC4: pinterest_awareness_imp | AD4: pinterest_awareness_spend | AE4: pinterest_conversion_imp | AF4: pinterest_conversion_spend | AG4: print_coop_spend | AH4: print_pure_spend | AI4: samples_quantity_distributed | AJ4: snap_awareness_imp | AK4: snap_awareness_spend | AL4: snap_conversion_imp | AM4: snap_conversion_spend | AN4: tiktok_awareness_imp | AO4: tiktok_awareness_spend | AP4: tv_coop_spend | AQ4: tv_pure_imp | AR4: tv_pure_spend +L1 | AS4: vday_dummy | AT4: xmas_dummy | AU4: youtube_video_spend | AV4: fbig_spend | AW4: fbig_imp +A60 | AX4: youtube_video_imp | AY4: outdoor_impressions +A20 | AZ4: outdoor_spend | BA4: covid_holiday_period | BB4: covid_xmas | BC4: tv_coop_spend_after_2020-04-13 | BD4: print_pure_spend_after_2020-04-13 +L1 | BE4: print_pure_spend_before_2020-04-13 | BF4: total_product_launch | BG4: week_before_laborday | BH4: week_before_vday +A30 | BI4: july_promo | BJ4: mothersday_2019 | BK4: blackfriday_2019 | BL4: friends_and_family_august_promo | BM4: flash_sale_promo | BN4: new_year
B5: {=_xlfn._xlws.FILTER(OFFSET(InputSheet!$D$8,0,0,InputSheet!$B$2,1),_xlfn.ANCHORARRAY(InputSheet!B8))} -> All | C5: {=_xlfn._xlws.FILTER(OFFSET(InputSheet!$E$8,0,0,InputSheet!$B$2,1),_xlfn.ANCHORARRAY(InputSheet!B8))} -> 43472 | D5: {=_xlfn._xlws.FILTER(OFFSET(InputSheet!$F$8,0,0,InputSheet!$B$2,InputSheet!$B$4),_xlfn.ANCHORARRAY(InputSheet!B8))} -> 6096762.5 | E5: 2900.8768 | F5: 8535.213 | G5: 0 | H5: 0 | I5: 6445.1076 | J5: 225599.02 | K5: 5970.834 | L5: 192.45043 | M5: 72160.543 | N5: 385.81377 | O5: 8048.5676 | P5: 301929.62 | Q5: 19863.905 | R5: 417.48972 | S5: 123341.35 | T5: 1587.0688 | U5: 21235 | V5: 0 | W5: 0.65777462 | X5: 0 | Y5: 2.4461557e+08 | Z5: 0 | AA5: 0 | AB5: 0 | AC5: 0 | AD5: 0 | AE5: 0 | AF5: 0 | AG5: 291.8426 | AH5: 68696.88 | AI5: 285111 | AJ5: 0 | AK5: 0 | AL5: 0 | AM5: 0 | AN5: 0 | AO5: 0 | AP5: 0 | AQ5: 0 | AR5: 0 | AS5: 0 | AT5: 0 | AU5: 6008.7616 | AV5: 0 | AW5: 0 | AX5: 532627.15 | AY5: 0 | AZ5: 0 | BA5: 0 | BB5: 0 | BC5: 0 | BD5: 0 | BE5: 68696.88 | BF5: 0.65777462 | BG5: 0 | BH5: 0 | BI5: 0 | BJ5: 0 | BK5: 0 | BL5: 0 | BM5: 0 | BN5: 0
B6: All | C6: 43479 | D6: 6089210.2 | E6: 2256.867 | F6: 7213.1737 | G6: 0 | H6: 0 | I6: 5744.4471 | J6: 207751.34 | K6: 5045.9974 | L6: 77.508639 | M6: 34493.547 | N6: 193.1763 | O6: 7100.4079 | P6: 270855.26 | Q6: 17575.176 | R6: 503.80616 | S6: 150301.58 | T6: 1892.74 | U6: 0 | V6: 0.038621946 | W6: 0.46331831 | X6: 0 | Y6: 2.5259263e+08 | Z6: 0 | AA6: 0 | AB6: 0 | AC6: 0 | AD6: 0 | AE6: 0 | AF6: 0 | AG6: 291.84229 | AH6: 128080.38 | AI6: 489603 | AJ6: 0 | AK6: 0 | AL6: 0 | AM6: 0 | AN6: 0 | AO6: 0 | AP6: 0 | AQ6: 0 | AR6: 0 | AS6: 0 | AT6: 0 | AU6: 4042.4816 | AV6: 0 | AW6: 0 | AX6: 363528.09 | AY6: 0 | AZ6: 0 | BA6: 0 | BB6: 0 | BC6: 0 | BD6: 0 | BE6: 128080.38 | BF6: 0.50194025 | BG6: 0 | BH6: 0 | BI6: 0 | BJ6: 0 | BK6: 0 | BL6: 0 | BM6: 0 | BN6: 0
B7: All | C7: 43486 | D7: 6508506.8 | E7: 834.12798 | F7: 7174.7345 | G7: 0 | H7: 0 | I7: 5925.4474 | J7: 211989.21 | K7: 5019.1072 | L7: 188.92731 | M7: 84085.864 | N7: 459.46324 | O7: 4985.6552 | P7: 198156.12 | Q7: 12181.654 | R7: 413.08582 | S7: 135798.22 | T7: 1711.4357 | U7: 0 | V7: 0.22152892 | W7: 0.37955382 | X7: 0 | Y7: 2.5558166e+08 | Z7: 0 | AA7: 0 | AB7: 0 | AC7: 0 | AD7: 0 | AE7: 0 | AF7: 0 | AG7: 291.84168 | AH7: 138871.58 | AI7: 302329 | AJ7: 0 | AK7: 0 | AL7: 0 | AM7: 0 | AN7: 0 | AO7: 0 | AP7: 0 | AQ7: 0 | AR7: 0 | AS7: 0 | AT7: 0 | AU7: 3810.1154 | AV7: 0 | AW7: 0 | AX7: 355039.52 | AY7: 0 | AZ7: 0 | BA7: 0 | BB7: 0 | BC7: 0 | BD7: 0 | BE7: 138871.58 | BF7: 0.60108275 | BG7: 0 | BH7: 0 | BI7: 0 | BJ7: 0 | BK7: 0 | BL7: 0 | BM7: 0 | BN7: 0
B8: All | C8: 43493 | D8: 7022937.1 | E8: 1875.3715 | F8: 7815.4707 | G8: 0 | H8: 0 | I8: 6411.1976 | J8: 261913.14 | K8: 5467.3361 | L8: 221.07578 | M8: 103102.34 | N8: 552.38057 | O8: 5072.412 | P8: 193075.78 | Q8: 12393.209 | R8: 726.20311 | S8: 313427.32 | T8: 3413.5203 | U8: 0 | V8: 0.023616164 | W8: 0 | X8: 0 | Y8: 2.4766957e+08 | Z8: 0 | AA8: 0 | AB8: 0 | AC8: 0 | AD8: 0 | AE8: 0 | AF8: 0 | AG8: 13837.331 | AH8: 0 | AI8: 371304 | AJ8: 0 | AK8: 0 | AL8: 0 | AM8: 0 | AN8: 0 | AO8: 0 | AP8: 0 | AQ8: 0 | AR8: 0 | AS8: 0 | AT8: 0 | AU8: 7283.5619 | AV8: 0 | AW8: 0 | AX8: 596112.99 | AY8: 0 | AZ8: 0 | BA8: 0 | BB8: 0 | BC8: 0 | BD8: 0 | BE8: 0 | BF8: 0.023616164 | BG8: 0 | BH8: 0 | BI8: 0 | BJ8: 0 | BK8: 0 | BL8: 0 | BM8: 0 | BN8: 0
B9: All | C9: 43500 | D9: 19633183 | E9: 2128.4428 | F9: 9028.5069 | G9: 0 | H9: 0 | I9: 7195.5322 | J9: 283329.31 | K9: 6315.9192 | L9: 1185.5299 | M9: 1881717.3 | N9: 6625.4674 | O9: 6423.0881 | P9: 227563.16 | Q9: 15256.219 | R9: 1536.9611 | S9: 1156974.1 | T9: 10973.407 | U9: 0 | V9: 0.032639321 | W9: 0.00132715 | X9: 0 | Y9: 3.0204759e+08 | Z9: 0 | AA9: 0 | AB9: 0 | AC9: 0 | AD9: 0 | AE9: 0 | AF9: 0 | AG9: 31897.984 | AH9: 102556.37 | AI9: 468574 | AJ9: 0 | AK9: 0 | AL9: 0 | AM9: 0 | AN9: 0 | AO9: 0 | AP9: 191864.99 | AQ9: 0 | AR9: 0 | AS9: 0 | AT9: 0 | AU9: 25594.411 | AV9: 0 | AW9: 0 | AX9: 2251435 | AY9: 0 | AZ9: 0 | BA9: 0 | BB9: 0 | BC9: 0 | BD9: 0 | BE9: 102556.37 | BF9: 0.033966471 | BG9: 0 | BH9: 1 | BI9: 0 | BJ9: 0 | BK9: 0 | BL9: 0 | BM9: 0 | BN9: 0
B10: All | C10: 43507 | D10: 12143474 | E10: 2207.1341 | F10: 9331.1159 | G10: 0 | H10: 0 | I10: 6759.9865 | J10: 293126.22 | K10: 6527.6103 | L10: 2989.8077 | M10: 5153010.8 | N10: 17620.744 | O10: 6428.8132 | P10: 230271.56 | Q10: 15424.668 | R10: 1894.1174 | S10: 1818067.3 | T10: 17235.529 | U10: 0 | V10: 0 | W10: 0.041399347 | X10: 0.00070642 | Y10: 3.4458308e+08 | Z10: 0 | AA10: 0 | AB10: 0 | AC10: 0 | AD10: 0 | AE10: 0 | AF10: 0 | AG10: 30455.078 | AH10: 0 | AI10: 208336 | AJ10: 0 | AK10: 0 | AL10: 0 | AM10: 0 | AN10: 0 | AO10: 0 | AP10: 191864.99 | AQ10: 0 | AR10: 0 | AS10: 1 | AT10: 0 | AU10: 28391.391 | AV10: 0 | AW10: 0 | AX10: 2549329 | AY10: 0 | AZ10: 0 | BA10: 0 | BB10: 0 | BC10: 0 | BD10: 0 | BE10: 0 | BF10: 0.042105767 | BG10: 0 | BH10: 0.3 | BI10: 0 | BJ10: 0 | BK10: 0 | BL10: 0 | BM10: 0 | BN10: 0
B11: All | C11: 43514 | D11: 9691781.5 | E11: 1704.7687 | F11: 7430.1603 | G11: 0 | H11: 0 | I11: 4640.8298 | J11: 161760.09 | K11: 5197.791 | L11: 1134.885 | M11: 1994596.3 | N11: 7583.5941 | O11: 6520.8547 | P11: 239695.47 | Q11: 15136.64 | R11: 1014.2182 | S11: 1171058.2 | T11: 10726.01 | U11: 0 | V11: 0 | W11: 0.019437 | X11: 0.042161779 | Y11: 2.956075e+08 | Z11: 0 | AA11: 0 | AB11: 0 | AC11: 0 | AD11: 0 | AE11: 0 | AF11: 0 | AG11: 12580.871 | AH11: 172271.21 | AI11: 829297 | AJ11: 0 | AK11: 0 | AL11: 0 | AM11: 0 | AN11: 0 | AO11: 0 | AP11: 191864.99 | AQ11: 0 | AR11: 0 | AS11: 0 | AT11: 0 | AU11: 12064.529 | AV11: 0 | AW11: 0 | AX11: 1120416 | AY11: 0 | AZ11: 0 | BA11: 0 | BB11: 0 | BC11: 0 | BD11: 0 | BE11: 172271.21 | BF11: 0.061598779 | BG11: 0 | BH11: 0.09 | BI11: 0 | BJ11: 0 | BK11: 0 | BL11: 0 | BM11: 0 | BN11: 0
B12: All | C12: 43521 | D12: 7689159.6 | E12: 1597.7485 | F12: 6198.8048 | G12: 0 | H12: 0 | I12: 3826.9891 | J12: 93100.647 | K12: 4336.3926 | L12: 1394.2747 | M12: 2431316.5 | N12: 8957.4623 | O12: 5998.9925 | P12: 229529.06 | Q12: 13790.822 | R12: 881.66077 | S12: 652310.07 | T12: 6222.9989 | U12: 0 | V12: 0.25167989 | W12: 0.0025707 | X12: 0.054890715 | Y12: 2.9142605e+08 | Z12: 0 | AA12: 0 | AB12: 0 | AC12: 0 | AD12: 0 | AE12: 0 | AF12: 0 | AG12: 13242.876 | AH12: 0 | AI12: 712828 | AJ12: 0 | AK12: 0 | AL12: 0 | AM12: 0 | AN12: 0 | AO12: 0 | AP12: 0 | AQ12: 0 | AR12: 0 | AS12: 0 | AT12: 0 | AU12: 9795.5138 | AV12: 0 | AW12: 0 | AX12: 901653.7 | AY12: 0 | AZ12: 0 | BA12: 0 | BB12: 0 | BC12: 0 | BD12: 0 | BE12: 0 | BF12: 0.3091413 | BG12: 0 | BH12: 0.027 | BI12: 0 | BJ12: 0 | BK12: 0 | BL12: 0 | BM12: 0 | BN12: 0
B13: All | C13: 43528 | D13: 10234522 | E13: 1814.3071 | F13: 7126.8902 | G13: 0 | H13: 0 | I13: 4476.5643 | J13: 171533.23 | K13: 4985.6375 | L13: 1411.4499 | M13: 2262162.7 | N13: 8559.8125 | O13: 5557.2814 | P13: 184579.78 | Q13: 13539.399 | R13: 1532.5572 | S13: 1031359.9 | T13: 9866.5972 | U13: 185897 | V13: 2.5620533 | W13: 0.0069388 | X13: 0.10726779 | Y13: 3.314311e+08 | Z13: 0 | AA13: 0 | AB13: 0 | AC13: 0 | AD13: 0 | AE13: 0 | AF13: 0 | AG13: 31621.187 | AH13: 0 | AI13: 673603 | AJ13: 0 | AK13: 0 | AL13: 0 | AM13: 0 | AN13: 0 | AO13: 0 | AP13: 28401.068 | AQ13: 0 | AR13: 0 | AS13: 0 | AT13: 0 | AU13: 9919.1396 | AV13: 0 | AW13: 0 | AX13: 885470.61 | AY13: 0 | AZ13: 0 | BA13: 0 | BB13: 0 | BC13: 0 | BD13: 0 | BE13: 0 | BF13: 2.6762598 | BG13: 0 | BH13: 0 | BI13: 0 | BJ13: 0 | BK13: 0 | BL13: 0 | BM13: 0 | BN13: 0
B14: All | C14: 43535 | D14: 9309029.2 | E14: 1716.1003 | F14: 9041.1667 | G14: 0 | H14: 0 | I14: 5948.3477 | J14: 275232.3 | K14: 6324.7754 | L14: 1650.1413 | M14: 2892995.4 | N14: 11191.914 | O14: 5203.6482 | P14: 171564.93 | Q14: 12826.262 | R14: 1916.5773 | S14: 1238496 | T14: 12756.787 | U14: 100412 | V14: 6.1382 | W14: 0.033388586 | X14: 1.0504388 | Y14: 3.1302486e+08 | Z14: 0 | AA14: 0 | AB14: 0 | AC14: 0 | AD14: 0 | AE14: 0 | AF14: 0 | AG14: 31806.192 | AH14: 124936.11 | AI14: 262005 | AJ14: 0 | AK14: 0 | AL14: 0 | AM14: 0 | AN14: 0 | AO14: 0 | AP14: 28401.068 | AQ14: 0 | AR14: 0 | AS14: 0 | AT14: 0 | AU14: 13554.999 | AV14: 0 | AW14: 0 | AX14: 1072549.2 | AY14: 0 | AZ14: 0 | BA14: 0 | BB14: 0 | BC14: 0 | BD14: 0 | BE14: 124936.11 | BF14: 7.2220274 | BG14: 0 | BH14: 0 | BI14: 0 | BJ14: 0 | BK14: 0 | BL14: 0 | BM14: 0 | BN14: 0
B15: All | C15: 43542 | D15: 12102723 | E15: 1461.1404 | F15: 9687.5569 | G15: 0 | H15: 0 | I15: 6383.0126 | J15: 302482.75 | K15: 6776.9596 | L15: 2128.4049 | M15: 3771744.4 | N15: 14381.077 | O15: 4656.6838 | P15: 160591.3 | Q15: 11685.269 | R15: 1142.812 | S15: 950705.56 | T15: 9198.0748 | U15: 3528 | V15: 13.436133 | W15: 0.0099693 | X15: 1.5849695 | Y15: 3.7821918e+08 | Z15: 0 | AA15: 0 | AB15: 0 | AC15: 0 | AD15: 0 | AE15: 365287.89 | AF15: 1466.832 | AG15: 1587.1126 | AH15: 0 | AI15: 449101 | AJ15: 0 | AK15: 0 | AL15: 0 | AM15: 0 | AN15: 0 | AO15: 0 | AP15: 28401.068 | AQ15: 0 | AR15: 0 | AS15: 0 | AT15: 0 | AU15: 19186.103 | AV15: 0 | AW15: 0 | AX15: 1485778.8 | AY15: 0 | AZ15: 0 | BA15: 0 | BB15: 0 | BC15: 0 | BD15: 0 | BE15: 0 | BF15: 15.031072 | BG15: 0 | BH15: 0 | BI15: 0 | BJ15: 0 | BK15: 0 | BL15: 0 | BM15: 1 | BN15: 0
B16: All | C16: 43549 | D16: 9283960.8 | E16: 1592.7123 | F16: 6094.4152 | G16: 0 | H16: 0 | I16: 4669.4551 | J16: 194113.78 | K16: 4263.3665 | L16: 1909.0906 | M16: 3270127.8 | N16: 13680.062 | O16: 5093.1103 | P16: 174979.28 | Q16: 13208.833 | R16: 995.28139 | S16: 646405.32 | T16: 6776.7154 | U16: 0 | V16: 10.22844 | W16: 0.033977548 | X16: 2.3107328 | Y16: 3.5580621e+08 | Z16: 0 | AA16: 0 | AB16: 0 | AC16: 0 | AD16: 0 | AE16: 1213088.5 | AF16: 5663.8375 | AG16: 476.88065 | AH16: 346712.64 | AI16: 632548 | AJ16: 0 | AK16: 0 | AL16: 0 | AM16: 0 | AN16: 0 | AO16: 0 | AP16: 0 | AQ16: 0 | AR16: 0 | AS16: 0 | AT16: 0 | AU16: 17619.136 | AV16: 0 | AW16: 0 | AX16: 1261825.2 | AY16: 0 | AZ16: 0 | BA16: 0 | BB16: 0 | BC16: 0 | BD16: 0 | BE16: 346712.64 | BF16: 12.57315 | BG16: 0 | BH16: 0 | BI16: 0 | BJ16: 0 | BK16: 0 | BL16: 0 | BM16: 0 | BN16: 0
B17: All | C17: 43556 | D17: 8030813.2 | E17: 1411.4075 | F17: 5280.9621 | G17: 0 | H17: 0 | I17: 4353.6955 | J17: 208962.85 | K17: 3694.313 | L17: 804.15213 | M17: 932129.47 | N17: 4133.3607 | O17: 5303.6167 | P17: 203297.67 | Q17: 12834.149 | R17: 1772.5697 | S17: 477717.01 | T17: 5269.9098 | U17: 3000 | V17: 10.776179 | W17: 0.48124695 | X17: 3.3550964 | Y17: 3.0530716e+08 | Z17: 0 | AA17: 0 | AB17: 0 | AC17: 0 | AD17: 0 | AE17: 342759.83 | AF17: 1968.2189 | AG17: 12306.024 | AH17: 0 | AI17: 367026 | AJ17: 0 | AK17: 0 | AL17: 0 | AM17: 0 | AN17: 0 | AO17: 0 | AP17: 59168.891 | AQ17: 0 | AR17: 0 | AS17: 0 | AT17: 0 | AU17: 9911.1563 | AV17: 0 | AW17: 0 | AX17: 776745.54 | AY17: 0 | AZ17: 0 | BA17: 0 | BB17: 0 | BC17: 0 | BD17: 0 | BE17: 0 | BF17: 14.612522 | BG17: 0 | BH17: 0 | BI17: 0 | BJ17: 0 | BK17: 0 | BL17: 0 | BM17: 0 | BN17: 0
... B108: All | C108: 44193 | D108: 5481824.2 | E108: 1677.6989 | F108: 16219.52 | G108: 0 | H108: -35.317458 | I108: 16333.625 | J108: 1173712.9 | K108: 11346.414 | L108: 15386.346 | M108: 8660576.7 | N108: 56061.991 | O108: 8088.2027 | P108: 127000.99 | Q108: 12319.752 | R108: 40.07549 | S108: 59596.657 | T108: 1072.7398 | U108: 1812 | V108: 17.748372 | W108: 8.2164651 | X108: 3.5181854 | Y108: 2.8733595e+08 | Z108: 0 | AA108: 0 | AB108: 0 | AC108: 626.16425 | AD108: 0 | AE108: 778984.46 | AF108: 3778.0326 | AG108: 0 | AH108: 0 | AI108: 499268 | AJ108: 172.72072 | AK108: 0 | AL108: 58.449217 | AM108: 0 | AN108: 2914031.3 | AO108: 27056.96 | AP108: 0 | AQ108: 0 | AR108: 0 | AS108: 0 | AT108: 0 | AU108: 39218.948 | AV108: 18749.434 | AW108: 20854669 | AX108: 1939259.6 | AY108: 0 | AZ108: 0 | BA108: 0 | BB108: 0 | BC108: 0 | BD108: 35426.906 | BE108: 0 | BF108: 29.483022 | BG108: 0 | BH108: 0 | BI108: 0 | BJ108: 0 | BK108: 0 | BL108: 0 | BM108: 0 | BN108: 0

Sheet Model
B1: ='Summary Data'!L3 -> 3 | C1: =COUNTA(G:G)-1 -> 35 | E1: ="'"&G1&"':{"&IF(H1="",""," 'lag':"&H1&",")&IF(I1="",""," 'adstock':"&I1&",")&IF(J1="",""," 'saturation':"&J1&",")&" 'coeff':"&K1&"}," -> '':{ 'coeff':},
C3: Note: if N/A's, update InputSheet tab
B4: Group 1 | C4: Source | E4: Freeze | F4: Notes | G4: Feature | H4: Lag | I4: Adstock | K4: Coeff | L4: T-stat | N4: Excel Name | O4: Tail Factor
B5: {=VLOOKUP(OFFSET($G$4,1,0,$C$1,1),feat[[Feature]:[Group 1]],2,0)} -> Seasonality | C5: {=MATCH(_xlfn.ANCHORARRAY(N5),_xlfn.ANCHORARRAY(IS!D4),0)} -> 60 | E5: ="'"&G5&"':{"&IF(H5="",""," 'lag': "&H5&",")&IF(I5="",""," 'adstock': "&I5&",")&IF(J5="",""," 'saturation': {'saturation_type': 'hill', 'S': "&INT(J5)&", 'K': "&MOD(J5,1)&"},")&" 'coeff': "&K5&"}," -> 'blackfriday_2019':{ 'lag': 0, 'adstock': 0, 'coeff': 3763559.37277432}, | G5: blackfriday_2019 | H5: 0 | I5: 0 | K5: 3763559.4 | L5: 3.5441694 | N5: {=OFFSET(G$4,1,0,$C$1,1)&TEXT(OFFSET(H$4,1,0,$C$1,1)," +L0;;;")&TEXT(OFFSET(I$4,1,0,$C$1,1)*100," +A0;;;")&TEXT(OFFSET(J$4,1,0,$C$1,1)," +""S""0.0;;;")} -> blackfriday_2019 | O5: {=(1-OFFSET(I4,1,0,$C$1,1)^100)/(1-OFFSET(I4,1,0,C1,1))-1} -> 0
B6: Seasonality | C6: 58 | E6: ="'"&G6&"':{"&IF(H6="",""," 'lag': "&H6&",")&IF(I6="",""," 'adstock': "&I6&",")&IF(J6="",""," 'saturation': {'saturation_type': 'hill', 'S': "&INT(J6)&", 'K': "&MOD(J6,1)&"},")&" 'coeff': "&K6&"}," -> 'july_promo':{ 'lag': 0, 'adstock': 0, 'coeff': 2258006.45629113}, | G6: july_promo | H6: 0 | I6: 0 | K6: 2258006.5 | L6: 3.0312712 | N6: july_promo | O6: 0
B7: Seasonality | C7: 43 | E7: ="'"&G7&"':{"&IF(H7="",""," 'lag': "&H7&",")&IF(I7="",""," 'adstock': "&I7&",")&IF(J7="",""," 'saturation': {'saturation_type': 'hill', 'S': "&INT(J7)&", 'K': "&MOD(J7,1)&"},")&" 'coeff': "&K7&"}," -> 'xmas_dummy':{ 'lag': 0, 'adstock': 0, 'coeff': -1294895.22821243}, | G7: xmas_dummy | H7: 0 | I7: 0 | K7: -1294895.2 | L7: -1.7051017 | N7: xmas_dummy | O7: 0
B8: GWP | C8: 62 | E8: ="'"&G8&"':{"&IF(H8="",""," 'lag': "&H8&",")&IF(I8="",""," 'adstock': "&I8&",")&IF(J8="",""," 'saturation': {'saturation_type': 'hill', 'S': "&INT(J8)&", 'K': "&MOD(J8,1)&"},")&" 'coeff': "&K8&"}," -> 'flash_sale_promo':{ 'lag': 0, 'adstock': 0, 'coeff': 2561008.43653139}, | G8: flash_sale_promo | H8: 0 | I8: 0 | K8: 2561008.4 | L8: 4.235376 | N8: flash_sale_promo | O8: 0
B9: Covid | C9: 5 | E9: ="'"&G9&"':{"&IF(H9="",""," 'lag': "&H9&",")&IF(I9="",""," 'adstock': "&I9&",")&IF(J9="",""," 'saturation': {'saturation_type': 'hill', 'S': "&INT(J9)&", 'K': "&MOD(J9,1)&"},")&" 'coeff': "&K9&"}," -> 'covid_trend':{ 'lag': 0, 'adstock': 0, 'coeff': 60357.349850606}, | G9: covid_trend | H9: 0 | I9: 0 | K9: 60357.35 | L9: 7.6350079 | N9: covid_trend | O9: 0
B10: Samples | C10: 32 | E10: ="'"&G10&"':{"&IF(H10="",""," 'lag': "&H10&",")&IF(I10="",""," 'adstock': "&I10&",")&IF(J10="",""," 'saturation': {'saturation_type': 'hill', 'S': "&INT(J10)&", 'K': "&MOD(J10,1)&"},")&" 'coeff': "&K10&"}," -> 'samples_quantity_distributed':{ 'lag': 0, 'adstock': 0, 'coeff': 1.43861046988365}, | G10: samples_quantity_distributed | H10: 0 | I10: 0 | K10: 1.4386105 | L10: 4.5334787 | N10: samples_quantity_distributed | O10: 0
B11: Facebook Instagram | C11: 46 | E11: ="'"&G11&"':{"&IF(H11="",""," 'lag': "&H11&",")&IF(I11="",""," 'adstock': "&I11&",")&IF(J11="",""," 'saturation': {'saturation_type': 'hill', 'S': "&INT(J11)&", 'K': "&MOD(J11,1)&"},")&" 'coeff': "&K11&"}," -> 'fbig_imp':{ 'lag': 0, 'adstock': 0.6, 'coeff': 0.0519931096026133}, | G11: fbig_imp | H11: 0 | I11: 0.6 | K11: 0.05199311 | L11: 4.7137717 | N11: fbig_imp +A60 | O11: 1.5
B12: Outdoor | C12: 48 | E12: ="'"&G12&"':{"&IF(H12="",""," 'lag': "&H12&",")&IF(I12="",""," 'adstock': "&I12&",")&IF(J12="",""," 'saturation': {'saturation_type': 'hill', 'S': "&INT(J12)&", 'K': "&MOD(J12,1)&"},")&" 'coeff': "&K12&"}," -> 'outdoor_impressions':{ 'lag': 0, 'adstock': 0.2, 'coeff': 0.101981686277872}, | G12: outdoor_impressions | H12: 0 | I12: 0.2 | K12: 0.10198169 | L12: 1.524268 | N12: outdoor_impressions +A20 | O12: 0.25
B13: #N/A | C13: 63 | E13: ="'"&G13&"':{"&IF(H13="",""," 'lag': "&H13&",")&IF(I13="",""," 'adstock': "&I13&",")&IF(J13="",""," 'saturation': {'saturation_type': 'hill', 'S': "&INT(J13)&", 'K': "&MOD(J13,1)&"},")&" 'coeff': "&K13&"}," -> 'new_year':{ 'lag': 0, 'adstock': 0, 'coeff': -488630.623596446}, | G13: new_year | H13: 0 | I13: 0 | K13: -488630.62 | L13: -0.46699037 | N13: new_year | O13: 0
B14: Seasonality | C14: 59 | E14: ="'"&G14&"':{"&IF(H14="",""," 'lag': "&H14&",")&IF(I14="",""," 'adstock': "&I14&",")&IF(J14="",""," 'saturation': {'saturation_type': 'hill', 'S': "&INT(J14)&", 'K': "&MOD(J14,1)&"},")&" 'coeff': "&K14&"}," -> 'mothersday_2019':{ 'lag': 0, 'adstock': 0, 'coeff': 12000000}, | G14: mothersday_2019 | H14: 0 | I14: 0 | K14: 12000000 | L14: 0 | N14: mothersday_2019 | O14: 0
B15: Seasonality | C15: 57 | E15: ="'"&G15&"':{"&IF(H15="",""," 'lag': "&H15&",")&IF(I15="",""," 'adstock': "&I15&",")&IF(J15="",""," 'saturation': {'saturation_type': 'hill', 'S': "&INT(J15)&", 'K': "&MOD(J15,1)&"},")&" 'coeff': "&K15&"}," -> 'week_before_vday':{ 'lag': 0, 'adstock': 0.3, 'coeff': 9000000}, | G15: week_before_vday | H15: 0 | I15: 0.3 | K15: 9000000 | L15: 0 | N15: week_before_vday +A30 | O15: 0.42857143
B16: Market | C16: 22 | E16: ="'"&G16&"':{"&IF(H16="",""," 'lag': "&H16&",")&IF(I16="",""," 'adstock': "&I16&",")&IF(J16="",""," 'saturation': {'saturation_type': 'hill', 'S': "&INT(J16)&", 'K': "&MOD(J16,1)&"},")&" 'coeff': "&K16&"}," -> 'market_sales':{ 'lag': 0, 'adstock': 0, 'coeff': 0.022}, | G16: market_sales | H16: 0 | I16: 0 | K16: 0.022 | L16: 0 | N16: market_sales | O16: 0
B17: Seasonality | C17: 50 | E17: ="'"&G17&"':{"&IF(H17="",""," 'lag': "&H17&",")&IF(I17="",""," 'adstock': "&I17&",")&IF(J17="",""," 'saturation': {'saturation_type': 'hill', 'S': "&INT(J17)&", 'K': "&MOD(J17,1)&"},")&" 'coeff': "&K17&"}," -> 'covid_holiday_period':{ 'lag': 0, 'adstock': 0, 'coeff': -1149319}, | G17: covid_holiday_period | H17: 0 | I17: 0 | K17: -1149319 | L17: 0 | N17: covid_holiday_period | O17: 0
B18: Seasonality | C18: 51 | E18: ="'"&G18&"':{"&IF(H18="",""," 'lag': "&H18&",")&IF(I18="",""," 'adstock': "&I18&",")&IF(J18="",""," 'saturation': {'saturation_type': 'hill', 'S': "&INT(J18)&", 'K': "&MOD(J18,1)&"},")&" 'coeff': "&K18&"}," -> 'covid_xmas':{ 'lag': 0, 'adstock': 0, 'coeff': -1732296}, | G18: covid_xmas | H18: 0 | I18: 0 | K18: -1732296 | L18: 0 | N18: covid_xmas | O18: 0
B19: Product Launch | C19: 55 | E19: ="'"&G19&"':{"&IF(H19="",""," 'lag': "&H19&",")&IF(I19="",""," 'adstock': "&I19&",")&IF(J19="",""," 'saturation': {'saturation_type': 'hill', 'S': "&INT(J19)&", 'K': "&MOD(J19,1)&"},")&" 'coeff': "&K19&"}," -> 'total_product_launch':{ 'lag': 0, 'adstock': 0, 'coeff': 2840.642889}, | G19: total_product_launch | H19: 0 | I19: 0 | K19: 2840.6429 | L19: 0 | N19: total_product_launch | O19: 0
B20: GWP | C20: 18 | E20: ="'"&G20&"':{"&IF(H20="",""," 'lag': "&H20&",")&IF(I20="",""," 'adstock': "&I20&",")&IF(J20="",""," 'saturation': {'saturation_type': 'hill', 'S': "&INT(J20)&", 'K': "&MOD(J20,1)&"},")&" 'coeff': "&K20&"}," -> 'gwp_units_distributed':{ 'lag': 0, 'adstock': 0, 'coeff': 9.734768}, | G20: gwp_units_distributed | H20: 0 | I20: 0 | K20: 9.734768 | L20: 0 | N20: gwp_units_distributed | O20: 0
B21: GWP | C21: 61 | E21: ="'"&G21&"':{"&IF(H21="",""," 'lag': "&H21&",")&IF(I21="",""," 'adstock': "&I21&",")&IF(J21="",""," 'saturation': {'saturation_type': 'hill', 'S': "&INT(J21)&", 'K': "&MOD(J21,1)&"},")&" 'coeff': "&K21&"}," -> 'friends_and_family_august_promo':{ 'lag': 0, 'adstock': 0, 'coeff': 4000000}, | G21: friends_and_family_august_promo | H21: 0 | I21: 0 | K21: 4000000 | L21: 0 | N21: friends_and_family_august_promo | O21: 0
B22: TV - Pure | C22: 41 | E22: ="'"&G22&"':{"&IF(H22="",""," 'lag': "&H22&",")&IF(I22="",""," 'adstock': "&I22&",")&IF(J22="",""," 'saturation': {'saturation_type': 'hill', 'S': "&INT(J22)&", 'K': "&MOD(J22,1)&"},")&" 'coeff': "&K22&"}," -> 'tv_pure_spend':{ 'lag': 1, 'adstock': 0, 'coeff': 1.1}, | G22: tv_pure_spend | H22: 1 | I22: 0 | K22: 1.1 | L22: 0 | N22: tv_pure_spend +L1 | O22: 0
